Workbook

Sheet Average Payroll Rankings
A1: Team | B1: Avg. Payroll (2011 - 2025)
A2: LAD | B2: 2.2989465e+08
A3: NYY | B3: 2.0902373e+08
A4: BOS | B4: 1.8825798e+08
A5: NYM | B5: 1.8063779e+08
A6: PHI | B6: 1.7271618e+08
A7: SF | B7: 165348328
A8: Rank | B8: Team | C8: Record | D8: Age | E8: Team Payroll | F8: Active Payroll
A9: 20 | B9: ARI | C9: 80-82 | D9: 27.4 | E9: 177424443 | F9: 68710886 | G9: 55771644 | H9: 1500000 | I9: 2303444
A10: 10 | B10: ARI | C10: 89-73 | D10: 28.9 | E10: 178427194 | F10: 134502970 | G10: 9600600 | H10: 7881888 | I10: 3160737
A11: 21 | B11: ARI | C11: 84-78 | D11: 27.6 | E11: 119296377 | F11: 60271739 | G11: 11201665 | H11: - | I11: 8620444
A12: 24 | B12: ARI | C12: 74-88 | D12: 27.8 | E12: 85966193 | F12: 53178906 | G12: 19224958 | H12: 500000 | I12: 3328922
A13: 19 | B13: ARI | C13: 52-110 | D13: 27.5 | E13: 91636935 | F13: 54233884 | G13: 8694478 | H13: 2500000 | I13: 2840361
A14: 27 | B14: ARI | C14: 25-35 | D14: 28.1 | E14: 65601868 | F14: 20286813 | G14: 1589593 | H14: 5600000 | I14: 500312
A15: 26 | B15: ARI | C15: 85-77 | D15: 27.8 | E15: 119327905 | F15: 65040742 | G15: 11699600 | H15: 550000 | I15: 16279980
A16: 12 | B16: ARI | C16: - | D16: 28.9 | E16: 141724597 | F16: 107901628 | G16: 14124025 | H16: 314516 | I16: 14068359
A17: 19 | B17: ARI | C17: - | D17: 28.3 | E17: 102619475 | F17: 81644775 | G17: 19379200 | H17: 150000 | I17: 23384
A18: 18 | B18: ARI | C18: - | D18: 26 | E18: 97874482 | F18: 78823003 | G18: 1051200 | H18: 3071443 | I18: 545188
A19: 28 | B19: ARI | C19: - | D19: 26 | E19: 76781801 | F19: 45142733 | G19: 1026500 | H19: 30465028 | I19: 147540
A20: 23 | B20: ARI | C20: - | D20: 27 | E20: 106343190 | F20: 68375588 | G20: 9500000 | H20: 18025819 | I20: 333330
A21: 17 | B21: ARI | C21: - | D21: 28.2 | E21: 88316478 | F21: 78126043 | G21: - | H21: 1607377 | I21: 273686
A22: 22 | B22: ARI | C22: - | D22: 28.6 | E22: 80711013 | F22: 74074400 | G22: - | H22: 750000 | I22: -
A23: 24 | B23: ARI | C23: - | D23: 28.5 | E23: 64297970 | F23: 56498519 | G23: - | H23: 1882500 | I23: 900000
A24: 25 | B24: ATH | C24: 76-86 | D24: 26.9 | E24: 78384241 | F24: 49340255 | G24: 15933681 | H24: - | I24: 941654
A25: 11 | B25: ATL | C25: 76-86 | D25: 29.5 | E25: 220223651 | F25: 128648209 | G25: 68078413 | H25: 3500000 | I25: 11733626
A26: 7 | B26: ATL | C26: 89-73 | D26: 30.9 | E26: 238108491 | F26: 156354098 | G26: 47028814 | H26: 5052328 | I26: 8296387
A27: 6 | B27: ATL | C27: 104-58 | D27: 28.5 | E27: 206424932 | F27: 158306501 | G27: 34160535 | H27: - | I27: 2510008
A28: 8 | B28: ATL | C28: 101-61 | D28: 29 | E28: 179935585 | F28: 143630429 | G28: 20918726 | H28: 1025000 | I28: 4675476
A29: 11 | B29: ATL | C29: 88-73 | D29: 28.2 | E29: 152753755 | F29: 115354620 | G29: 3301950 | H29: 14566935 | I29: 2956717
A30: 10 | B30: ATL | C30: 35-25 | D30: 29.1 | E30: 63561931 | F30: 50458292 | G30: 7255497 | H30: 500000 | I30: 3847858
A31: 11 | B31: ATL | C31: 97-65 | D31: 28.7 | E31: 143947963 | F31: 117758736 | G31: 8328689 | H31: 6000000 | I31: 68632
A32: 21 | B32: ATL | C32: - | D32: 27.1 | E32: 130852350 | F32: 73767565 | G32: 13299094 | H32: 19166668 | I32: 1392736
A33: 18 | B33: ATL | C33: - | D33: 27.5 | E33: 106468575 | F33: 81963434 | G33: 1997766 | H33: - | I33: 1469392
A34: 27 | B34: ATL | C34: - | D34: 26.7 | E34: 95839382 | F34: 46676093 | G34: 8116832 | H34: 19283609 | I34: 305280
A35: 24 | B35: ATL | C35: - | D35: 26.9 | E35: 110777379 | F35: 54961789 | G35: 11263899 | H35: 44307649 | I35: 244042
A36: 13 | B36: ATL | C36: - | D36: 27 | E36: 116865707 | F36: 102713304 | G36: - | H36: 13350000 | I36: 51911
A37: 14 | B37: ATL | C37: - | D37: 27.7 | E37: 94947950 | F37: 94401592 | G37: - | H37: - | I37: 343386
A38: 17 | B38: ATL | C38: - | D38: 28.4 | E38: 97928056 | F38: 86492616 | G38: - | H38: 11435440 | I38: -
A39: 13 | B39: ATL | C39: - | D39: 28.7 | E39: 98344460 | F39: 97919860 | G39: - | H39: 424600 | I39: -
A40: 21 | B40: BAL | C40: 75-87 | D40: 27.3 | E40: 158571377 | F40: 64226457 | G40: 29850106 | H40: - | I40: 6713671
...

Sheet Playoff Apearances  - Win%
C2: TEAM | D2: W | E2: L | F2: W% | G2: G | H2: AB | I2: R | J2: H | K2: 2B | L2: 3B | M2: HR | N2: RBI | O2: BB | P2: HBP | Q2: SO | R2: SB | S2: CS | T2: PA | U2: TB | V2: XBH | W2: SH | X2: SF | Y2: IBB | Z2: GIDP | AA2: AVG | AB2: OBP | AC2: SLG | AD2: OPS
C3: ARI | D3: 13 | E3: 13 | F3: 0.5 | G3: 26 | H3: 886 | I3: 120 | J3: 229 | K3: 32 | L3: 6 | M3: 40 | N3: 118 | O3: 84 | P3: 5 | Q3: 245 | R3: 29 | S3: 5 | T3: 991 | U3: 393 | V3: 78 | W3: 10 | X3: 6 | Y3: 6 | Z3: 17 | AA3: 0.258 | AB3: 0.324 | AC3: 0.444 | AD3: 0.768
C4: ATH/OAK | D4: 7 | E4: 13 | F4: 0.35 | G4: 20 | H4: 661 | I4: 71 | J4: 146 | K4: 17 | L4: 3 | M4: 26 | N4: 67 | O4: 64 | P4: 5 | Q4: 201 | R4: 3 | S4: 1 | T4: 738 | U4: 247 | V4: 46 | W4: 3 | X4: 5 | Y4: 4 | Z4: 11 | AA4: 0.221 | AB4: 0.293 | AC4: 0.374 | AD4: 0.666
C5: ATL | D5: 26 | E5: 30 | F5: 0.464 | G5: 56 | H5: 1870 | I5: 198 | J5: 411 | K5: 69 | L5: 7 | M5: 61 | N5: 194 | O5: 164 | P5: 15 | Q5: 562 | R5: 18 | S5: 5 | T5: 2061 | U5: 677 | V5: 137 | W5: 4 | X5: 8 | Y5: 13 | Z5: 21 | AA5: 0.22 | AB5: 0.287 | AC5: 0.362 | AD5: 0.649
C6: BAL | D6: 6 | E6: 13 | F6: 0.316 | G6: 19 | H6: 658 | I6: 62 | J6: 138 | K6: 24 | L6: 0 | M6: 14 | N6: 61 | O6: 43 | P6: 7 | Q6: 159 | R6: 9 | S6: 2 | T6: 715 | U6: 204 | V6: 38 | W6: 3 | X6: 4 | Y6: 1 | Z6: 9 | AA6: 0.21 | AB6: 0.264 | AC6: 0.31 | AD6: 0.574
C7: BOS | D7: 30 | E7: 21 | F7: 0.588 | G7: 51 | H7: 1742 | I7: 247 | J7: 423 | K7: 88 | L7: 6 | M7: 58 | N7: 237 | O7: 185 | P7: 18 | Q7: 468 | R7: 25 | S7: 6 | T7: 1964 | U7: 697 | V7: 152 | W7: 8 | X7: 11 | Y7: 15 | Z7: 39 | AA7: 0.243 | AB7: 0.32 | AC7: 0.4 | AD7: 0.72
C8: CHC | D8: 23 | E8: 24 | F8: 0.489 | G8: 47 | H8: 1529 | I8: 157 | J8: 316 | K8: 57 | L8: 5 | M8: 58 | N8: 152 | O8: 126 | P8: 21 | Q8: 455 | R8: 25 | S8: 5 | T8: 1694 | U8: 557 | V8: 120 | W8: 12 | X8: 6 | Y8: 13 | Z8: 24 | AA8: 0.207 | AB8: 0.275 | AC8: 0.364 | AD8: 0.64
C9: CHW | D9: 2 | E9: 5 | F9: =D9/SUM(E9,D9) -> 0.28571429 | G9: =SUM(D9:E9) -> 7
C10: CIN | D10: 2 | E10: 9 | F10: =D10/G10 -> 0.18181818 | G10: =SUM(D10:E10) -> 11
C11: CLE | D11: 21 | E11: 25 | F11: 0.457 | G11: 46 | H11: 1526 | I11: 156 | J11: 330 | K11: 63 | L11: 1 | M11: 43 | N11: 146 | O11: 128 | P11: 17 | Q11: 446 | R11: 20 | S11: 5 | T11: 1690 | U11: 524 | V11: 107 | W11: 12 | X11: 7 | Y11: 11 | Z11: 30 | AA11: 0.216 | AB11: 0.283 | AC11: 0.343 | AD11: 0.626
C12: COL | D12: 1 | E12: 1 | F12: 0.5 | G12: 2
C13: DE | D13: 25 | E13: 28 | F13: 0.472 | G13: 53 | H13: 1792 | I13: 179 | J13: 415 | K13: 80 | L13: 2 | M13: 49 | N13: 167 | O13: 168 | P13: 23 | Q13: 477 | R13: 21 | S13: 8 | T13: 2003 | U13: 646 | V13: 131 | W13: 17 | X13: 3 | Y13: 18 | Z13: 47 | AA13: 0.232 | AB13: 0.305 | AC13: 0.36 | AD13: 0.666
C14: FLA/MIA | D14: 2 | E14: 3 | F14: =D14/G14 -> 0.4 | G14: =SUM(D14:E14) -> 5
C15: HOU | D15: 62 | E15: 43 | F15: 0.59 | G15: 105 | H15: 3569 | I15: 473 | J15: 877 | K15: 144 | L15: 5 | M15: 151 | N15: 456 | O15: 366 | P15: 50 | Q15: 868 | R15: 44 | S15: 11 | T15: 4011 | U15: 1484 | V15: 300 | W15: 10 | X15: 16 | Y15: 31 | Z15: 80 | AA15: 0.246 | AB15: 0.323 | AC15: 0.416 | AD15: 0.739
C16: KC | D16: 25 | E16: 12 | F16: 0.676 | G16: 37 | H16: 1272 | I16: 174 | J16: 322 | K16: 57 | L16: 5 | M16: 30 | N16: 165 | O16: 98 | P16: 16 | Q16: 261 | R16: 33 | S16: 10 | T16: 1415 | U16: 479 | V16: 92 | W16: 12 | X16: 17 | Y16: 10 | Z16: 24 | AA16: 0.253 | AB16: 0.311 | AC16: 0.377 | AD16: 0.687
C17: LAA | D17: 0 | E17: 0 | F17: 0 | G17: 0
C18: LAD | D18: 77 | E18: 59 | F18: 0.566 | G18: 136 | H18: 4574 | I18: 605 | J18: 1078 | K18: 191 | L18: 20 | M18: 177 | N18: 580 | O18: 523 | P18: 60 | Q18: 1253 | R18: 86 | S18: 17 | T18: 5221 | U18: 1840 | V18: 388 | W18: 35 | X18: 29 | Y18: 53 | Z18: 84 | AA18: 0.236 | AB18: 0.32 | AC18: 0.402 | AD18: 0.723
C19: MIL | D19: 16 | E19: 26 | F19: 0.381 | G19: 42 | H19: 1383 | I19: 139 | J19: 321 | K19: 72 | L19: 4 | M19: 42 | N19: 134 | O19: 121 | P19: 16 | Q19: 377 | R19: 25 | S19: 6 | T19: 1537 | U19: 527 | V19: 118 | W19: 8 | X19: 9 | Y19: 11 | Z19: 29 | AA19: 0.232 | AB19: 0.3 | AC19: 0.381 | AD19: 0.681
C20: MIN | D20: 3 | E20: 12 | F20: 0.2 | G20: 15 | H20: 476 | I20: 38 | J20: 96 | K20: 19 | L20: 1 | M20: 15 | N20: 36 | O20: 60 | P20: 7 | Q20: 155 | R20: 4
C21: NYM | D21: 16 | E21: 15 | F21: 0.516 | G21: 31 | H21: 1027 | I21: 134 | J21: 233 | K21: 30 | L21: 5 | M21: 36 | N21: 132 | O21: 109 | P21: 18 | Q21: 284 | R21: 19 | S21: 4 | T21: 1175 | U21: 381 | V21: 71 | W21: 6 | X21: 15 | Y21: 8 | Z21: 20 | AA21: 0.227 | AB21: 0.308 | AC21: 0.371 | AD21: 0.679
C22: NYY | D22: 42 | E22: 47 | F22: 0.472 | G22: 89 | H22: 2968 | I22: 374 | J22: 660 | K22: 115 | L22: 11 | M22: 117 | N22: 360 | O22: 346 | P22: 27 | Q22: 853 | R22: 47 | S22: 10 | T22: 3377 | U22: 1148 | V22: 243 | W22: 8 | X22: 28 | Y22: 21 | Z22: 51 | AA22: 0.222 | AB22: 0.307 | AC22: 0.387 | AD22: 0.693
C23: PHI | D23: 28 | E23: 24 | F23: 0.538 | G23: 52 | H23: 1673 | I23: 217 | J23: 370 | K23: 86 | L23: 5 | M23: 61 | N23: 205 | O23: 175 | P23: 29 | Q23: 460 | R23: 41 | S23: 10 | T23: 1903 | U23: 649 | V23: 152 | W23: 12 | X23: 14 | Y23: 21 | Z23: 28 | AA23: 0.221 | AB23: 0.304 | AC23: 0.388 | AD23: 0.691
C24: PIT | D24: 3 | E24: 5 | F24: 0.375 | G24: 8 | H24: 251 | I24: 21 | J24: 54 | K24: 7 | L24: 0 | M24: 7 | N24: 21 | O24: 18 | P24: 3 | Q24: 63 | R24: 1 | S24: 1 | T24: 277 | U24: 82 | V24: 14 | W24: 2 | X24: 3 | Y24: 3 | Z24: 6 | AA24: 0.215 | AB24: 0.273 | AC24: 0.327 | AD24: 0.599
C25: SD | D25: 13 | E25: 15 | F25: 0.464 | G25: 28 | H25: 925 | I25: 113 | J25: 208 | K25: 33 | L25: 3 | M25: 36 | N25: 110 | O25: 76 | P25: 12 | Q25: 245 | R25: 12 | S25: 3 | T25: 1025 | U25: 355 | V25: 72 | W25: 5 | X25: 7 | Y25: 4 | Z25: 11 | AA25: 0.225 | AB25: 0.29 | AC25: 0.384 | AD25: 0.674
C26: SEA | D26: 8 | E26: 9 | F26: 0.471 | G26: 17 | H26: 611 | I26: 72 | J26: 133 | K26: 26 | L26: 2 | M26: 24 | N26: 69 | O26: 65 | P26: 9 | Q26: 188 | R26: 8 | S26: 3 | T26: 690 | U26: 235 | V26: 52 | W26: 1 | X26: 4 | Y26: 6 | Z26: 13 | AA26: 0.218 | AB26: 0.3 | AC26: 0.385 | AD26: 0.685
C27: SF | D27: 38 | E27: 20 | F27: 0.655 | G27: 58 | H27: 1971 | I27: 225 | J27: 470 | K27: 82 | L27: 12 | M27: 40 | N27: 210 | O27: 163 | P27: 11 | Q27: 472 | R27: 15 | S27: 14 | T27: 2182 | U27: 696 | V27: 134 | W27: 22 | X27: 15 | Y27: 12 | Z27: 29 | AA27: 0.238 | AB27: 0.298 | AC27: 0.353 | AD27: 0.651
C28: STL | D28: 36 | E28: 40 | F28: 0.474 | G28: 76 | H28: 2526 | I28: 316 | J28: 587 | K28: 124 | L28: 10 | M28: 70 | N28: 294 | O28: 236 | P28: 35 | Q28: 620 | R28: 31 | S28: 9 | T28: 2844 | U28: 941 | V28: 204 | W28: 31 | X28: 16 | Y28: 33 | Z28: 50 | AA28: 0.232 | AB28: 0.305 | AC28: 0.373 | AD28: 0.678
C29: TB | D29: 20 | E29: 28 | F29: 0.417 | G29: 48 | H29: 1599 | I29: 174 | J29: 341 | K29: 58 | L29: 4 | M29: 69 | N29: 170 | O29: 137 | P29: 15 | Q29: 515 | R29: 15 | S29: 11 | T29: 1757 | U29: 614 | V29: 131 | W29: 2 | X29: 4 | Y29: 5 | Z29: 30 | AA29: 0.213 | AB29: 0.281 | AC29: 0.384 | AD29: 0.665
C30: TEX | D30: 33 | E30: 26 | F30: 0.559 | G30: 59 | H30: 2039 | I30: 283 | J30: 507 | K30: 99 | L30: 6 | M30: 77 | N30: 268 | O30: 187 | P30: 19 | Q30: 444 | R30: 37 | S30: 15 | T30: 2268 | U30: 849 | V30: 182 | W30: 11 | X30: 12 | Y30: 20 | Z30: 46 | AA30: 0.249 | AB30: 0.316 | AC30: 0.416 | AD30: 0.732
C31: TOR | D31: 20 | E31: 24 | F31: 0.455 | G31: 44 | H31: 1553 | I31: 205 | J31: 394 | K31: 78 | L31: 5 | M31: 58 | N31: 194 | O31: 137 | P31: 21 | Q31: 355 | R31: 16 | S31: 3 | T31: 1729 | U31: 656 | V31: 141 | W31: 9 | X31: 9 | Y31: 16 | Z31: 34 | AA31: 0.254 | AB31: 0.321 | AC31: 0.422 | AD31: 0.743
C32: WSH | D32: 19 | E32: 17 | F32: 0.528 | G32: 36 | H32: 1221 | I32: 147 | J32: 274 | K32: 47 | L32: 3 | M32: 40 | N32: 140 | O32: 132 | P32: 12 | Q32: 343 | R32: 17 | S32: 1 | T32: 1387 | U32: 447 | V32: 90 | W32: 13 | X32: 9 | Y32: 13 | Z32: 16 | AA32: 0.224 | AB32: 0.304 | AC32: 0.366 | AD32: 0.67

Sheet Largest Free Agent Signing
A1: Team | B1: Player | C1: Term | D1: Value | E1: Signed
A2: ARI | B2: Corbin Burnes | C2: 6 | D2: 210000000 | E2: 45654
A3: ATH/OAK | B3: Luis Severino | C3: 3 | D3: 67000000 | E3: 45631
A4: ATL | B4: Austin Riley | C4: 10 | D4: 212000000 | E4: 44774
A5: BAL | B5: Chris Davis | C5: 7 | D5: 161000000 | E5: 42390
A6: BOS | B6: Rafael Devers | C6: 10 | D6: 313500000 | E6: 44930
A7: CHC | B7: Jason Heyward | C7: 8 | D7: 184000000 | E7: 42353
A8: CHW | B8: Andrew Benintendi | C8: 5 | D8: 75000000 | E8: 44911
A9: CIN | B9: Joey Votto | C9: 10 | D9: 225000000 | E9: 41001
A10: CLE | B10: Jose Ramirez | C10: 7 | D10: 129000000 | E10: 44657
A11: COL | B11: Nolan Arenado | C11: 7 | D11: 234000000 | E11: 43522
A12: DET | B12: Miguel Cabrera | C12: 8 | D12: 248000000 | E12: 41729
A13: FLA/MIA | B13: Giancarlo Stanton | C13: 13 | D13: 325000000 | E13: 41961
... A31: WSH | B31: Stephen Strasburg | C31: 7 | D31: 245000000 | E31: 43808

Sheet CP 6 Regression
A1: SUMMARY OUTPUT
A3: Regression Statistics
A4: Multiple R | B4: 0.61821877
A5: R Square | B5: 0.38219445
A6: Adjusted R Square | B6: 0.36012996
A7: Standard Error | B7: 25.000325
A8: Observations | B8: 30
A10: ANOVA
B11: df | C11: SS | D11: MS | E11: F | F11: Significance F
A12: Regression | B12: 1 | C12: 10826.346 | D12: 10826.346 | E12: 17.321703 | F12: 0.00027180907
A13: Residual | B13: 28 | C13: 17500.454 | D13: 625.01623
A14: Total | B14: 29 | C14: 28326.8
B16: Coefficients | C16: Standard Error | D16: t Stat | E16: P-value | F16: Lower 95% | G16: Upper 95% | H16: Lower 95.0% | I16: Upper 95.0%
A17: Intercept | B17: -21.772691 | C17: 15.712117 | D17: -1.3857261 | E17: 0.1767697 | F17: -53.957504 | G17: 10.412123 | H17: -53.957504 | I17: 10.412123
A18: Avg. Payroll (2011 - 2025) | B18: 4.7732733e-07 | C18: 1.146888e-07 | D18: 4.161935 | E18: 0.00027180907 | F18: 2.4239797e-07 | G18: 7.1225668e-07 | H18: 2.4239797e-07 | I18: 7.1225668e-07

Sheet CP 7 Regression
A1: SUMMARY OUTPUT
A3: Regression Statistics
A4: Multiple R | B4: 0.61821877
A5: R Square | B5: 0.38219445
A6: Adjusted R Square | B6: 0.36012996
A7: Standard Error | B7: 25.000325
A8: Observations | B8: 30
A10: ANOVA
B11: df | C11: SS | D11: MS | E11: F | F11: Significance F
A12: Regression | B12: 1 | C12: 10826.346 | D12: 10826.346 | E12: 17.321703 | F12: 0.00027180907
A13: Residual | B13: 28 | C13: 17500.454 | D13: 625.01623
A14: Total | B14: 29 | C14: 28326.8
B16: Coefficients | C16: Standard Error | D16: t Stat | E16: P-value | F16: Lower 95% | G16: Upper 95% | H16: Lower 95.0% | I16: Upper 95.0%
A17: Intercept | B17: -21.772691 | C17: 15.712117 | D17: -1.3857261 | E17: 0.1767697 | F17: -53.957504 | G17: 10.412123 | H17: -53.957504 | I17: 10.412123
A18: Relative Payroll | B18: 62.572691 | C18: 15.034519 | D18: 4.161935 | E18: 0.00027180907 | F18: 31.775875 | G18: 93.369506 | H18: 31.775875 | I18: 93.369506
B22: Metric | C22: CP6 (Avg Payroll) | D22: CP7 (Relative Payroll)
B23: Predictor(s) | C23: Average Payroll (raw dollars) | D23: Relative Payroll (ratio vs league avg)
B24: R² | C24: 0.382 | D24: 0.382 (essentially unchanged)
B25: Adjusted R² | C25: 0.36 | D25: 0.36
B26: F-statistic | C26: 17.32 | D26: 17.32
B27: Significance F | C27: 0.00027 | D27: 0.00027
B28: Payroll Coefficient | C28: very small (≈ 4.8e-7) | D28: 62.57
B29: Payroll P-value | C29: 0.00027 | D29: 0.00027
B30: Interpretability | C30: Weak (due to scale of dollars) | D30: Strong (games per 1.0 payroll index)
B31: Observations | C31: 30 | D31: 30

Sheet DataDictionary
A1: Team | B1: Avg. Payroll (2011 - 2025) | D1: W | E1: L | F1: W% | G1: G | I1: Years | J1: Value | K1: AAV | L1: Signed | M1: Player | O1: Team | P1: Owner | Q1: Net Worth (USD)
A2: ='Average Payroll Rankings'!A279 -> ARI | B2: ='Average Payroll Rankings'!B279 -> 1.0642333e+08 | D2: ='Playoff Apearances - Win%'!D3 -> 13 | E2: ='Playoff Apearances - Win%'!E3 -> 13 | F2: ='Playoff Apearances - Win%'!F3 -> 0.5 | G2: ='Playoff Apearances - Win%'!G3 -> 26 | I2: ='Largest Free Agent Signing'!C2 -> 6 | J2: ='Largest Free Agent Signing'!D2 -> 210000000 | K2: =J2/I2 -> 35000000 | L2: ='Largest Free Agent Signing'!E2 -> 45654 | M2: ='Largest Free Agent Signing'!B2 -> Corbin Burnes | O2: ARI | P2: Ken Kendrick | Q2: 600000000
A3: ='Average Payroll Rankings'!A287 -> ATH/OAK | B3: ='Average Payroll Rankings'!B287 -> 72760230 | D3: ='Playoff Apearances - Win%'!D4 -> 7 | E3: ='Playoff Apearances - Win%'!E4 -> 13 | F3: ='Playoff Apearances - Win%'!F4 -> 0.35 | G3: ='Playoff Apearances - Win%'!G4 -> 20 | I3: ='Largest Free Agent Signing'!C3 -> 3 | J3: ='Largest Free Agent Signing'!D3 -> 67000000 | K3: =J3/I3 -> 22333333 | L3: ='Largest Free Agent Signing'!E3 -> 45631 | M3: ='Largest Free Agent Signing'!B3 -> Luis Severino | O3: ATH/OAK | P3: John Fisher | Q3: 2600000000
A4: ='Average Payroll Rankings'!A90 -> ATL | B4: ='Average Payroll Rankings'!B90 -> 1.3713201e+08 | D4: ='Playoff Apearances - Win%'!D5 -> 26 | E4: ='Playoff Apearances - Win%'!E5 -> 30 | F4: ='Playoff Apearances - Win%'!F5 -> 0.464 | G4: ='Playoff Apearances - Win%'!G5 -> 56 | I4: ='Largest Free Agent Signing'!C4 -> 10 | J4: ='Largest Free Agent Signing'!D4 -> 212000000 | K4: =J4/I4 -> 21200000 | L4: ='Largest Free Agent Signing'!E4 -> 44774 | M4: ='Largest Free Agent Signing'!B4 -> Austin Riley | O4: ATL | P4: Liberty Media (John Malone) | Q4: 8000000000
A5: ='Average Payroll Rankings'!A283 -> BAL | B5: ='Average Payroll Rankings'!B283 -> 99300083 | D5: ='Playoff Apearances - Win%'!D6 -> 6 | E5: ='Playoff Apearances - Win%'!E6 -> 13 | F5: ='Playoff Apearances - Win%'!F6 -> 0.316 | G5: ='Playoff Apearances - Win%'!G6 -> 19 | I5: ='Largest Free Agent Signing'!C5 -> 7 | J5: ='Largest Free Agent Signing'!D5 -> 161000000 | K5: =J5/I5 -> 23000000 | L5: ='Largest Free Agent Signing'!E5 -> 42390 | M5: ='Largest Free Agent Signing'!B5 -> Chris Davis | O5: BAL | P5: Peter Angelos | Q5: 2000000000
A6: ='Average Payroll Rankings'!A4 -> BOS | B6: ='Average Payroll Rankings'!B4 -> 1.8825798e+08 | D6: ='Playoff Apearances - Win%'!D7 -> 30 | E6: ='Playoff Apearances - Win%'!E7 -> 21 | F6: ='Playoff Apearances - Win%'!F7 -> 0.588 | G6: ='Playoff Apearances - Win%'!G7 -> 51 | I6: ='Largest Free Agent Signing'!C6 -> 10 | J6: ='Largest Free Agent Signing'!D6 -> 313500000 | K6: =J6/I6 -> 31350000 | L6: ='Largest Free Agent Signing'!E6 -> 44930 | M6: ='Largest Free Agent Signing'!B6 -> Rafael Devers | O6: BOS | P6: John Henry | Q6: 3600000000
A7: ='Average Payroll Rankings'!A86 -> CHC | B7: ='Average Payroll Rankings'!B86 -> 1.5807043e+08 | D7: ='Playoff Apearances - Win%'!D8 -> 23 | E7: ='Playoff Apearances - Win%'!E8 -> 24 | F7: ='Playoff Apearances - Win%'!F8 -> 0.489 | G7: ='Playoff Apearances - Win%'!G8 -> 47 | I7: ='Largest Free Agent Signing'!C7 -> 8 | J7: ='Largest Free Agent Signing'!D7 -> 184000000 | K7: =J7/I7 -> 23000000 | L7: ='Largest Free Agent Signing'!E7 -> 42353 | M7: ='Largest Free Agent Signing'!B7 -> Jason Heyward | O7: CHC | P7: Ricketts family | Q7: 4500000000
A8: ='Average Payroll Rankings'!A97 -> CHW | B8: ='Average Payroll Rankings'!B97 -> 1.1452784e+08 | D8: ='Playoff Apearances - Win%'!D9 -> 2 | E8: ='Playoff Apearances - Win%'!E9 -> 5 | F8: ='Playoff Apearances - Win%'!F9 -> 0.28571429 | G8: ='Playoff Apearances - Win%'!G9 -> 7 | I8: ='Largest Free Agent Signing'!C8 -> 5 | J8: ='Largest Free Agent Signing'!D8 -> 75000000 | K8: =J8/I8 -> 15000000 | L8: ='Largest Free Agent Signing'!E8 -> 44911 | M8: ='Largest Free Agent Signing'!B8 -> Andrew Benintendi | O8: CHW | P8: Jerry Reinsdorf | Q8: 1700000000
A9: ='Average Payroll Rankings'!A282 -> CIN | B9: ='Average Payroll Rankings'!B282 -> 1.0199998e+08 | D9: ='Playoff Apearances - Win%'!D10 -> 2 | E9: ='Playoff Apearances - Win%'!E10 -> 9 | F9: ='Playoff Apearances - Win%'!F10 -> 0.18181818 | G9: ='Playoff Apearances - Win%'!G10 -> 11 | I9: ='Largest Free Agent Signing'!C9 -> 10 | J9: ='Largest Free Agent Signing'!D9 -> 225000000 | K9: =J9/I9 -> 22500000 | L9: ='Largest Free Agent Signing'!E9 -> 41001 | M9: ='Largest Free Agent Signing'!B9 -> Joey Votto | O9: CIN | P9: Robert H. Castellini | Q9: 400000000
A10: ='Average Payroll Rankings'!A284 -> CLE | B10: ='Average Payroll Rankings'!B284 -> 88724101 | D10: ='Playoff Apearances - Win%'!D11 -> 21 | E10: ='Playoff Apearances - Win%'!E11 -> 25 | F10: ='Playoff Apearances - Win%'!F11 -> 0.457 | G10: ='Playoff Apearances - Win%'!G11 -> 46 | I10: ='Largest Free Agent Signing'!C10 -> 7 | J10: ='Largest Free Agent Signing'!D10 -> 129000000 | K10: =J10/I10 -> 18428571 | L10: ='Largest Free Agent Signing'!E10 -> 44657 | M10: ='Largest Free Agent Signing'!B10 -> Jose Ramirez | O10: CLE | P10: Dolan family | Q10: 4600000000
A11: ='Average Payroll Rankings'!A96 -> COL | B11: ='Average Payroll Rankings'!B96 -> 117714881 | D11: ='Playoff Apearances - Win%'!D12 -> 1 | E11: ='Playoff Apearances - Win%'!E12 -> 1 | F11: ='Playoff Apearances - Win%'!F12 -> 0.5 | G11: ='Playoff Apearances - Win%'!G12 -> 2 | I11: ='Largest Free Agent Signing'!C11 -> 7 | J11: ='Largest Free Agent Signing'!D11 -> 234000000 | K11: =J11/I11 -> 33428571 | L11: ='Largest Free Agent Signing'!E11 -> 43522 | M11: ='Largest Free Agent Signing'!B11 -> Nolan Arenado | O11: COL | P11: Richard L. Monfort | Q11: 700000000
A12: ='Average Payroll Rankings'!A92 -> DET | B12: ='Average Payroll Rankings'!B92 -> 1.349975e+08 | D12: ='Playoff Apearances - Win%'!D13 -> 25 | E12: ='Playoff Apearances - Win%'!E13 -> 28 | F12: ='Playoff Apearances - Win%'!F13 -> 0.472 | G12: ='Playoff Apearances - Win%'!G13 -> 53 | I12: ='Largest Free Agent Signing'!C12 -> 8 | J12: ='Largest Free Agent Signing'!D12 -> 248000000 | K12: =J12/I12 -> 31000000 | L12: ='Largest Free Agent Signing'!E12 -> 41729 | M12: ='Largest Free Agent Signing'!B12 -> Miguel Cabrera | O12: DET | P12: Ilitch Holdings | Q12: 3800000000
A13: ='Average Payroll Rankings'!A285 -> FLA/ MIA | B13: ='Average Payroll Rankings'!B285 -> 75294152 | D13: ='Playoff Apearances - Win%'!D14 -> 2 | E13: ='Playoff Apearances - Win%'!E14 -> 3 | F13: ='Playoff Apearances - Win%'!F14 -> 0.4 | G13: ='Playoff Apearances - Win%'!G14 -> 5 | I13: ='Largest Free Agent Signing'!C13 -> 13 | J13: ='Largest Free Agent Signing'!D13 -> 325000000 | K13: =J13/I13 -> 25000000 | L13: ='Largest Free Agent Signing'!E13 -> 41961 | M13: ='Largest Free Agent Signing'!B13 -> Giancarlo Stanton | O13: FLA/MIA | P13: Bruce Sherman | Q13: 500000000
A14: ='Average Payroll Rankings'!A91 -> HOU | B14: ='Average Payroll Rankings'!B91 -> 1.3658589e+08 | D14: ='Playoff Apearances - Win%'!D15 -> 62 | E14: ='Playoff Apearances - Win%'!E15 -> 43 | F14: ='Playoff Apearances - Win%'!F15 -> 0.59 | G14: ='Playoff Apearances - Win%'!G15 -> 105 | I14: ='Largest Free Agent Signing'!C14 -> 6 | J14: ='Largest Free Agent Signing'!D14 -> 157500000 | K14: =J14/I14 -> 26250000 | L14: ='Largest Free Agent Signing'!E14 -> 43179 | M14: ='Largest Free Agent Signing'!B14 -> Jose Altuve | O14: HOU | P14: Jim Crane | Q14: 1400000000
A15: ='Average Payroll Rankings'!A281 -> KC | B15: ='Average Payroll Rankings'!B281 -> 1.0204845e+08 | D15: ='Playoff Apearances - Win%'!D16 -> 25 | E15: ='Playoff Apearances - Win%'!E16 -> 12 | F15: ='Playoff Apearances - Win%'!F16 -> 0.676 | G15: ='Playoff Apearances - Win%'!G16 -> 37 | I15: ='Largest Free Agent Signing'!C15 -> 11 | J15: ='Largest Free Agent Signing'!D15 -> 289000000 | K15: =J15/I15 -> 26272727 | L15: ='Largest Free Agent Signing'!E15 -> 45327 | M15: ='Largest Free Agent Signing'!B15 -> Bobby Witt Jr. | O15: KC | P15: John Sherman | Q15: 1250000000
A16: ='Average Payroll Rankings'!A85 -> LAA | B16: ='Average Payroll Rankings'!B85 -> 1.6464592e+08 | D16: ='Playoff Apearances - Win%'!D17 -> 0 | E16: ='Playoff Apearances - Win%'!E17 -> 0 | F16: ='Playoff Apearances - Win%'!F17 -> 0 | G16: ='Playoff Apearances - Win%'!G17 -> 0 | I16: ='Largest Free Agent Signing'!C16 -> 10 | J16: ='Largest Free Agent Signing'!D16 -> 360000000 | K16: =J16/I16 -> 36000000 | L16: ='Largest Free Agent Signing'!E16 -> 43545 | M16: ='Largest Free Agent Signing'!B16 -> Mike Trout | O16: LAA | P16: Arturo Moreno | Q16: 3600000000
A17: ='Average Payroll Rankings'!A2 -> LAD | B17: ='Average Payroll Rankings'!B2 -> 2.2989465e+08 | D17: ='Playoff Apearances - Win%'!D18 -> 77 | E17: ='Playoff Apearances - Win%'!E18 -> 59 | F17: ='Playoff Apearances - Win%'!F18 -> 0.566 | G17: ='Playoff Apearances - Win%'!G18 -> 136 | I17: ='Largest Free Agent Signing'!C17 -> 10 | J17: ='Largest Free Agent Signing'!D17 -> 700000000 | K17: =J17/I17 -> 70000000 | L17: ='Largest Free Agent Signing'!E17 -> 45269 | M17: ='Largest Free Agent Signing'!B17 -> Shohei Ohtani | O17: LAD | P17: Guggenheim Baseball Management (Mark Walter) | Q17: 5000000000
A18: ='Average Payroll Rankings'!A280 -> MIL | B18: ='Average Payroll Rankings'!B280 -> 1.0242304e+08 | D18: ='Playoff Apearances - Win%'!D19 -> 16 | E18: ='Playoff Apearances - Win%'!E19 -> 26 | F18: ='Playoff Apearances - Win%'!F19 -> 0.381 | G18: ='Playoff Apearances - Win%'!G19 -> 42 | I18: ='Largest Free Agent Signing'!C18 -> 7 | J18: ='Largest Free Agent Signing'!D18 -> 188500000 | K18: =J18/I18 -> 26928571 | L18: ='Largest Free Agent Signing'!E18 -> 43896 | M18: ='Largest Free Agent Signing'!B18 -> Christian Yelich | O18: MIL | P18: Mark Attanasio | Q18: 700000000
A19: ='Average Payroll Rankings'!A98 -> MIN | B19: ='Average Payroll Rankings'!B98 -> 1.1360592e+08 | D19: ='Playoff Apearances - Win%'!D20 -> 3 | E19: ='Playoff Apearances - Win%'!E20 -> 12 | F19: ='Playoff Apearances - Win%'!F20 -> 0.2 | G19: ='Playoff Apearances - Win%'!G20 -> 15 | I19: ='Largest Free Agent Signing'!C19 -> 6 | J19: ='Largest Free Agent Signing'!D19 -> 200000000 | K19: =J19/I19 -> 33333333 | L19: ='Largest Free Agent Signing'!E19 -> 44936 | M19: ='Largest Free Agent Signing'!B19 -> Carlos Correa | O19: MIN | P19: Pohlad family | Q19: 3800000000
A20: ='Average Payroll Rankings'!A5 -> NYM | B20: ='Average Payroll Rankings'!B5 -> 1.8063779e+08 | D20: ='Playoff Apearances - Win%'!D21 -> 16 | E20: ='Playoff Apearances - Win%'!E21 -> 15 | F20: ='Playoff Apearances - Win%'!F21 -> 0.516 | G20: ='Playoff Apearances - Win%'!G21 -> 31 | I20: ='Largest Free Agent Signing'!C20 -> 15 | J20: ='Largest Free Agent Signing'!D20 -> 765000000 | K20: =J20/I20 -> 51000000 | L20: ='Largest Free Agent Signing'!E20 -> 45634 | M20: ='Largest Free Agent Signing'!B20 -> Juan Soto | O20: NYM | P20: Steve Cohen | Q20: 15900000000
A21: ='Average Payroll Rankings'!A3 -> NYY | B21: ='Average Payroll Rankings'!B3 -> 2.0902373e+08 | D21: ='Playoff Apearances - Win%'!D22 -> 42 | E21: ='Playoff Apearances - Win%'!E22 -> 47 | F21: ='Playoff Apearances - Win%'!F22 -> 0.472 | G21: ='Playoff Apearances - Win%'!G22 -> 89 | I21: ='Largest Free Agent Signing'!C21 -> 9 | J21: ='Largest Free Agent Signing'!D21 -> 360000000 | K21: =J21/I21 -> 40000000 | L21: ='Largest Free Agent Signing'!E21 -> 44902 | M21: ='Largest Free Agent Signing'!B21 -> Aaron Judge | O21: NYY | P21: Steinbrenner family | Q21: 3800000000
A22: ='Average Payroll Rankings'!A6 -> PHI | B22: ='Average Payroll Rankings'!B6 -> 1.7271618e+08 | D22: ='Playoff Apearances - Win%'!D23 -> 28 | E22: ='Playoff Apearances - Win%'!E23 -> 24 | F22: ='Playoff Apearances - Win%'!F23 -> 0.538 | G22: ='Playoff Apearances - Win%'!G23 -> 52 | I22: ='Largest Free Agent Signing'!C22 -> 13 | J22: ='Largest Free Agent Signing'!D22 -> 330000000 | K22: =J22/I22 -> 25384615 | L22: ='Largest Free Agent Signing'!E22 -> 43524 | M22: ='Largest Free Agent Signing'!B22 -> Bryce Harper | O22: PHI | P22: John Middleton | Q22: 3400000000
A23: ='Average Payroll Rankings'!A286 -> PIT | B23: ='Average Payroll Rankings'!B286 -> 73389085 | D23: ='Playoff Apearances - Win%'!D24 -> 3 | E23: ='Playoff Apearances - Win%'!E24 -> 5 | F23: ='Playoff Apearances - Win%'!F24 -> 0.375 | G23: ='Playoff Apearances - Win%'!G24 -> 8 | I23: ='Largest Free Agent Signing'!C23 -> 7 | J23: ='Largest Free Agent Signing'!D23 -> 100000000 | K23: =J23/I23 -> 14285714 | L23: ='Largest Free Agent Signing'!E23 -> 45042 | M23: ='Largest Free Agent Signing'!B23 -> Bryan Reynolds | O23: PIT | P23: Bob Nutting | Q23: 1100000000
A24: ='Average Payroll Rankings'!A94 -> SD | B24: ='Average Payroll Rankings'!B94 -> 1.2457145e+08 | D24: ='Playoff Apearances - Win%'!D25 -> 13 | E24: ='Playoff Apearances - Win%'!E25 -> 15 | F24: ='Playoff Apearances - Win%'!F25 -> 0.464 | G24: ='Playoff Apearances - Win%'!G25 -> 28 | I24: ='Largest Free Agent Signing'!C24 -> 14 | J24: ='Largest Free Agent Signing'!D24 -> 340000000 | K24: =J24/I24 -> 24285714 | L24: ='Largest Free Agent Signing'!E24 -> 44249 | M24: ='Largest Free Agent Signing'!B24 -> Fernando Tatis Jr. | O24: SD | P24: Peter Seidler / Seidler Equity Partners | Q24: 3000000000
A25: ='Average Payroll Rankings'!A95 -> SEA | B25: ='Average Payroll Rankings'!B95 -> 1.2091473e+08 | D25: ='Playoff Apearances - Win%'!D26 -> 8 | E25: ='Playoff Apearances - Win%'!E26 -> 9 | F25: ='Playoff Apearances - Win%'!F26 -> 0.471 | G25: ='Playoff Apearances - Win%'!G26 -> 17 | I25: ='Largest Free Agent Signing'!C25 -> 10 | J25: ='Largest Free Agent Signing'!D25 -> 240000000 | K25: =J25/I25 -> 24000000 | L25: ='Largest Free Agent Signing'!E25 -> 41620 | M25: ='Largest Free Agent Signing'!B25 -> Robinson Cano | O25: SEA | P25: John Stanton | Q25: 1100000000
A26: ='Average Payroll Rankings'!A7 -> SF | B26: ='Average Payroll Rankings'!B7 -> 165348328 | D26: ='Playoff Apearances - Win%'!D27 -> 38 | E26: ='Playoff Apearances - Win%'!E27 -> 20 | F26: ='Playoff Apearances - Win%'!F27 -> 0.655 | G26: ='Playoff Apearances - Win%'!G27 -> 58 | I26: ='Largest Free Agent Signing'!C26 -> 7 | J26: ='Largest Free Agent Signing'!D26 -> 182000000 | K26: =J26/I26 -> 26000000 | L26: ='Largest Free Agent Signing'!E26 -> 45633 | M26: ='Largest Free Agent Signing'!B26 -> Willy Adames | O26: SF | P26: Charles B. Johnson | Q26: 5800000000
A27: ='Average Payroll Rankings'!A89 -> STL | B27: ='Average Payroll Rankings'!B89 -> 1.3940189e+08 | D27: ='Playoff Apearances - Win%'!D28 -> 36 | E27: ='Playoff Apearances - Win%'!E28 -> 40 | F27: ='Playoff Apearances - Win%'!F28 -> 0.474 | G27: ='Playoff Apearances - Win%'!G28 -> 76 | I27: ='Largest Free Agent Signing'!C27 -> 5 | J27: ='Largest Free Agent Signing'!D27 -> 130000000 | K27: =J27/I27 -> 26000000 | L27: ='Largest Free Agent Signing'!E27 -> 43548 | M27: ='Largest Free Agent Signing'!B27 -> Paul Goldschmidt | O27: STL | P27: William DeWitt Jr. | Q27: 4000000000
A28: ='Average Payroll Rankings'!A288 -> TB | B28: ='Average Payroll Rankings'!B288 -> 71519542 | D28: ='Playoff Apearances - Win%'!D29 -> 20 | E28: ='Playoff Apearances - Win%'!E29 -> 28 | F28: ='Playoff Apearances - Win%'!F29 -> 0.417 | G28: ='Playoff Apearances - Win%'!G29 -> 48 | I28: ='Largest Free Agent Signing'!C28 -> 11 | J28: ='Largest Free Agent Signing'!D28 -> 182000000 | K28: =J28/I28 -> 16545455 | L28: ='Largest Free Agent Signing'!E28 -> 44527 | M28: ='Largest Free Agent Signing'!B28 -> Wander Franco | O28: TB | P28: Stuart Sternberg | Q28: 800000000
A29: ='Average Payroll Rankings'!A87 -> TEX | B29: ='Average Payroll Rankings'!B87 -> 1.5311101e+08 | D29: ='Playoff Apearances - Win%'!D30 -> 33 | E29: ='Playoff Apearances - Win%'!E30 -> 26 | F29: ='Playoff Apearances - Win%'!F30 -> 0.559 | G29: ='Playoff Apearances - Win%'!G30 -> 59 | I29: ='Largest Free Agent Signing'!C29 -> 10 | J29: ='Largest Free Agent Signing'!D29 -> 325000000 | K29: =J29/I29 -> 32500000 | L29: ='Largest Free Agent Signing'!E29 -> 44531 | M29: ='Largest Free Agent Signing'!B29 -> Corey Seager | O29: TEX | P29: Ray Davis | Q29: 2200000000
A30: ='Average Payroll Rankings'!A88 -> TOR | B30: ='Average Payroll Rankings'!B88 -> 1.4926619e+08 | D30: ='Playoff Apearances - Win%'!D31 -> 20 | E30: ='Playoff Apearances - Win%'!E31 -> 24 | F30: ='Playoff Apearances - Win%'!F31 -> 0.455 | G30: ='Playoff Apearances - Win%'!G31 -> 44 | I30: ='Largest Free Agent Signing'!C30 -> 14 | J30: ='Largest Free Agent Signing'!D30 -> 500000000 | K30: =J30/I30 -> 35714286 | L30: ='Largest Free Agent Signing'!E30 -> 45753 | M30: ='Largest Free Agent Signing'!B30 -> Vladimir Guerrero Jr. | O30: TOR | P30: Rogers Communications (Edward Rogers III) | Q30: 11500000000
A31: ='Average Payroll Rankings'!A93 -> WSH | B31: ='Average Payroll Rankings'!B93 -> 1.2838433e+08 | D31: ='Playoff Apearances - Win%'!D32 -> 19 | E31: ='Playoff Apearances - Win%'!E32 -> 17 | F31: ='Playoff Apearances - Win%'!F32 -> 0.528 | G31: ='Playoff Apearances - Win%'!G32 -> 36 | I31: ='Largest Free Agent Signing'!C31 -> 7 | J31: ='Largest Free Agent Signing'!D31 -> 245000000 | K31: =J31/I31 -> 35000000 | L31: ='Largest Free Agent Signing'!E31 -> 43808 | M31: ='Largest Free Agent Signing'!B31 -> Stephen Strasburg | O31: WSH | P31: Lerner family | Q31: 4900000000
A63: NL | B63: Payroll | C63: AL | D63: Payroll
A64: ARI | B64: =VLOOKUP(A64,A2:B31,2) -> 1.0642333e+08 | C64: ATH/OAK | D64: =VLOOKUP(C64,A2:B31,2) -> 72760230
A65: ATL | B65: =VLOOKUP(A65,A3:B32,2) -> 1.3713201e+08 | C65: BAL | D65: =VLOOKUP(C65,A3:B32,2) -> 99300083 | F65: Correlaion | G65: =CORREL(B2:B31,G2:G31) -> 0.61821877
A66: CHC | B66: =VLOOKUP(A66,A4:B33,2) -> 1.5807043e+08 | C66: BOS | D66: =VLOOKUP(C66,A4:B33,2) -> 1.8825798e+08
A67: CIN | B67: =VLOOKUP(A67,A5:B34,2) -> 1.0199998e+08 | C67: CHW | D67: =VLOOKUP(C67,A5:B34,2) -> 1.1452784e+08
A68: COL | B68: =VLOOKUP(A68,A6:B35,2) -> 117714881 | C68: CLE | D68: =VLOOKUP(C68,A6:B35,2) -> 88724101
A69: FLA/ MIA | B69: =VLOOKUP(A69,A7:B36,2) -> 75294152 | C69: DET | D69: =VLOOKUP(C69,A7:B36,2) -> 1.349975e+08
A70: LAD | B70: =VLOOKUP(A70,A8:B37,2) -> 2.2989465e+08 | C70: HOU | D70: =VLOOKUP(C70,A8:B37,2) -> 1.3658589e+08
A71: MIL | B71: =VLOOKUP(A71,A9:B38,2) -> 1.0242304e+08 | C71: KC | D71: =VLOOKUP(C71,A9:B38,2) -> 1.0204845e+08
...

Sheet Relationships
